<?xml version="1.0" ?>
<robot name="rosbot">
  
  <link name="base_link">
    <visual name="base_link_visual">
      <origin rpy=" 1.5707 0 1.5707" xyz="0 0 0.1"/>
      <geometry>
        <mesh filename="package://autopilot/models/upper.dae" scale="0.001 0.001 0.001"/>
      </geometry>
    </visual>
  </link>

  <joint name="front_left_wheel_hinge" type="continuous">
    <!-- <origin rpy="0 0 0" xyz="0.05 0.11 0"/> -->
    <child link="front_left_wheel"/>
    <parent link="base_link"/>
    <!-- <axis rpy="0 0 0" xyz="0 1 0"/> -->
    <!-- <limit effort="1" velocity="10"/> -->
    <!-- <joint_properties damping="5.0" friction="1.0"/> -->
  </joint>

  <link name="front_left_wheel">
    <visual name="front_left_wheel_visual">
      <origin rpy="0 0 1.5707" xyz="0 0 0"/>
      <geometry>
        <mesh filename="package://autopilot/models/wheel.dae" scale="0.001 0.001 0.001"/>
      </geometry>
    </visual>
  </link>

  <joint name="front_right_wheel_hinge" type="continuous">
    <!-- <origin rpy="0 0 0" xyz="0.05 -0.11 0"/> -->
    <child link="front_right_wheel"/>
    <parent link="base_link"/>
    <!-- <axis rpy="0 0 0" xyz="0 1 0"/> -->
    <!-- <limit effort="1" velocity="10"/> -->
    <!-- <joint_properties damping="5.0" friction="1.0"/> -->
  </joint>

  <link name="front_right_wheel">
    <visual name="front_right_wheel_visual">
      <origin rpy="0 0 -1.5707" xyz="0 0 0"/>
      <geometry>
        <mesh filename="package://autopilot/models/wheel.dae" scale="0.001 0.001 0.001"/>
      </geometry>
    </visual>
  </link>

  <joint name="rear_left_wheel_hinge" type="continuous">
    <!-- <origin rpy="0 0 0" xyz="-0.055 0.11 0"/> -->
    <child link="rear_left_wheel"/>
    <parent link="base_link"/>
    <!-- <axis rpy="0 0 0" xyz="0 1 0"/>
    <limit effort="1" velocity="10"/>
    <joint_properties damping="5.0" friction="1.0"/> -->
  </joint>

  <link name="rear_left_wheel">
    <visual name="rear_left_wheel_visual">
      <origin rpy="0 0 1.5707" xyz="0 0 0"/>
      <geometry>
        <mesh filename="package://autopilot/models/wheel.dae" scale="0.001 0.001 0.001"/>
      </geometry>
    </visual>
  </link>

  <joint name="rear_right_wheel_hinge" type="continuous">
    <!-- <origin rpy="0 0 0" xyz="-0.055 -0.11 0"/> -->
    <child link="rear_right_wheel"/>
    <parent link="base_link"/>
    <!-- <axis rpy="0 0 0" xyz="0 1 0"/>
    <limit effort="1" velocity="10"/>
    <joint_properties damping="5.0" friction="1.0"/> -->
  </joint>

  <link name="rear_right_wheel">
    <visual name="rear_right_wheel_visual">
      <origin rpy="0 0 -1.5707" xyz="0 0 0"/>
      <geometry>
        <mesh filename="package://autopilot/models/wheel.dae" scale="0.001 0.001 0.001"/>
      </geometry>
    </visual>
  </link>

</robot>