<?xml version="1.0"?>
<sdf version='1.7'>
  <model name='mars_robot'>
    <pose>0 0 0.0 0 0 0</pose>

    <link name='mars_robot_footprint'></link>
    <link name='robot_base_link'>
      <visual name='robot_base_link_visual'>
        <pose> 0 0 0.1115 0 0 0</pose>
        <geometry>
          <box>
            <size>0.326 0.2142 0.175</size>
          </box>
        </geometry>
        <material>
          <script>
            <name>Gazebo/Red</name>
            <uri>file://media/materials/scripts/gazebo.material</uri> 
          </script>
        </material>
      </visual>
      <collision name='robot_base_link_collision'>
        <pose>0 0 0.1115 0 0 0</pose>
        <geometry>
          <box>
            <size>0.326 0.2142 0.300</size>
          </box>
        </geometry>
      </collision>
      <inertial>
        <pose>0.000112 2.3e-05 0.00015 0 -0 0</pose>
        <mass>4.43</mass>
        <inertia>
          <ixx>0.0330025</ixx>
          <ixy>-4.93883e-06</ixy>
          <ixz>-3.28432e-05</ixz>
          <iyy>0.0553027</iyy>
          <iyz>-6.63499e-06</iyz>
          <izz>0.0560386</izz>
        </inertia>
      </inertial>
    </link>
    
    <joint name="base_joint" type="fixed">  
      <origin xyz="0.0 0.0 0.0615"/> 
      <parent>mars_robot_footprint</parent>
      <child>robot_base_link</child>            
    </joint>
    
    <link name='camera_link'>
      <pose> 0.1335 0 0.2045 0 0 0</pose>
      <visual name='camera_link_visual'>
        <geometry>
          <box>
            <size>0.03 0.11 0.035</size> 
          </box>
        </geometry>
        <material>
          <script>
            <name>Gazebo/Orange</name>
              <uri>file://media/materials/scripts/gazebo.material</uri> 
          </script>
        </material>
      </visual>
      <sensor name="camera" type="camera">
        <!-- <pose>0 0 0 0 1.57079632679 3.14159265359</pose> -->
        <pose>0 0 0 0 0 0</pose>
        <camera>
          <horizontal_fov>1.047</horizontal_fov>
          <image>
            <width>1280</width>
            <height>720</height>
          </image>
          <clip>
            <near>0.1</near>
            <far>100</far>
          </clip>
        </camera>
        <always_on>1</always_on>
        <update_rate>30</update_rate>
        <visualize>false</visualize>
        <plugin name="camera_driver" filename="libgazebo_ros_camera.so" />
      </sensor>      
    </link>

    <link name="camera_link_optical"></link>

    <joint name="camera_joint" type="fixed">
          <origin rpy="0 0 0" xyz="0.1335 0 0.2045"></origin>
          <parent>robot_base_link</parent>
          <child>camera_link</child>
    </joint>

    <joint name="camera_optical_joint" type="fixed">
          <!-- these values have to be these values otherwise the gazebo camera image
          won't be aligned properly with the frame it is supposedly originating from  -->
          <origin xyz="0 0 0" rpy="${-pi/2} 0 ${-pi/2}"></origin>
          <parent>camera_link</parent>
          <child>camera_link_optical</child>
    </joint>

    <link name="imu_link">
      <inertial>
        <mass>0.001</mass>
        <pose>0 0 0 0 0 0</pose>
        <inertia>
          <ixx>1e-09</ixx>
          <ixy>0.0</ixy>
          <ixz>0.0</ixz>
          <iyy>1e-09</iyy>
          <iyz>0.0</iyz>
          <izz>1e-09</izz>
        </inertia>
      </inertial>
      <sensor name="imu" type="imu">
        <always_on>true</always_on>
        <update_rate>250</update_rate>
        <imu>
          <angular_velocity>
            <x>
              <noise type="gaussian">
                <mean>0.0</mean>
                <stddev>2e-5</stddev>
              </noise>
            </x>
            <y>
              <noise type="gaussian">
                <mean>0.0</mean>
                <stddev>2e-5</stddev>
              </noise>
            </y>
            <z>
              <noise type="gaussian">
                <mean>0.0</mean>
                <stddev>2e-5</stddev>
              </noise>
            </z>
          </angular_velocity>
          <linear_acceleration>
            <x>
              <noise type="gaussian">
                <mean>0.0</mean>
                <stddev>1.7e-3</stddev>
              </noise>
            </x>
            <y>
              <noise type="gaussian">
                <mean>0.0</mean>
                <stddev>1.7e-3</stddev>
              </noise>
            </y>
            <z>
              <noise type="gaussian">
                <mean>0.0</mean>
                <stddev>1.7e-3</stddev>
              </noise>
            </z>
          </linear_acceleration>
        </imu>
        <plugin name="mars_robot_imu" filename="libgazebo_ros_imu_sensor.so">
          <ros>
            <remapping>~/out:=imu</remapping>
          </ros>
        </plugin>
      </sensor>
    </link>

    <joint name="imu_joint" type="fixed">
      <parent>robot_base_link</parent>
      <child>imu_link</child>
      <origin xyz="0.0495 0.01 0.0665" rpy="0 0 0"></origin>
    </joint>
    <!-- WHEELS -->
    <joint name='front_left_wheel_joint' type='revolute'>
            <pose relative_to='robot_base_link'>0.0955 0.141 0 1.5708 0 0</pose>
            <parent>robot_base_link</parent>
            <child>front_left_wheel_link</child>
            <axis>
              <xyz> 0 0 -1</xyz>
              <use_parent_model_frame>true</use_parent_model_frame>
              <limit>
                <lower>-1e+16</lower>
                <upper>1e+16</upper>
              </limit>
              <dynamics>
                <spring_reference>0</spring_reference>
                <spring_stiffness>0</spring_stiffness>
              </dynamics>
            </axis>
            <physics>
            <ode>
                <limit>
                  <cfm>0.000000</cfm>
                  <erp>0.900000</erp>
                </limit>
              </ode>
            </physics>
    </joint>

    <link name='front_left_wheel_link'>
      <pose relative_to='front_left_wheel_joint'>0 0 0 0 0 0</pose>
      <inertial>
        <pose>0 0 0 0 -0 0</pose>
        <mass>0.176</mass>
        <inertia>
          <ixx>0.000287467</ixx>
          <ixy>0</ixy>
          <ixz>0</ixz>
          <iyy>0.000287467</iyy>
          <iyz>0</iyz>
          <izz>3.0184e-05</izz>
        </inertia>
      </inertial>
      <collision name='front_left_wheel_link_collision'>
        <geometry>
          <cylinder>
            <length>0.0615</length>
            <radius>0.068</radius>
          </cylinder>
        </geometry>
        <surface>
          <friction>
            <ode>
              <mu>2</mu>
              <mu2>2</mu2>
              <slip1>0.0</slip1>
              <slip2>0.0</slip2>
            </ode>
          </friction>
        </surface>
      </collision>
      <visual name='front_left_wheel_link_visual'>
        <pose>0 0 0 0 0 0</pose>
        <geometry>
          <cylinder>
            <length>0.0615</length>
            <radius>0.068</radius>
          </cylinder>
        </geometry>
        <material>
          <script>
            <name>Gazebo/Black</name>
          </script>
        </material>
      </visual>
    </link>     

    <joint name='front_right_wheel_joint' type='revolute'>
      <pose relative_to='robot_base_link'>0.0955 -0.141 0 1.5708 0 0</pose>
      <parent>robot_base_link</parent>
      <child>front_right_wheel_link</child>
      <axis>
          <xyz>0 0 -1</xyz>
          <use_parent_model_frame>true</use_parent_model_frame>
          <limit>
            <lower>-1e+16</lower>
            <upper>1e+16</upper>
          </limit>
          <dynamics>
            <spring_reference>0</spring_reference>
            <spring_stiffness>0</spring_stiffness>
          </dynamics>
        </axis>
        <physics>
          <ode>
            <limit>
              <cfm>0.000000</cfm>
              <erp>0.900000</erp>
            </limit>
          </ode>
        </physics>
    </joint>

    <link name='front_right_wheel_link'>
      <pose relative_to='front_right_wheel_joint'>0 0 0 0 0 0</pose>
      <inertial>
        <pose>0 0 0 0 0 0</pose>
        <mass>0.176</mass>
        <inertia>
          <ixx>0.000287467</ixx>
          <ixy>0</ixy>
          <ixz>0</ixz>
          <iyy>0.000287467</iyy>
          <iyz>0</iyz>
          <izz>3.0184e-05</izz>
        </inertia>
      </inertial>
      <collision name='front_right_wheel_link_collision'>
        <pose>0 0 0 0 0 0</pose>
        <geometry>
          <cylinder>
            <length>0.0615</length>
            <radius>0.068</radius>
          </cylinder>
        </geometry>
        <surface>
          <friction>
            <ode>
              <mu>2</mu>
              <mu2>2</mu2>
              <slip1>0.0</slip1>
              <slip2>0.0</slip2>
            </ode>
          </friction>
        </surface>
      </collision>
      <visual name='front_right_wheel_link_visual'>
        <pose>0 0 0 0 0 0</pose>
        <geometry>
          <cylinder>
            <length>0.0615</length>
            <radius>0.068</radius>
          </cylinder>
        </geometry>
        <material>
          <script>
            <name>Gazebo/Black</name>
            <uri>file://media/materials/scripts/gazebo.material</uri> 
          </script>
        </material>
      </visual>
    </link>

    <joint name='rear_left_wheel_joint' type='revolute'>
      <pose relative_to='robot_base_link'>-0.0955 0.141 0 1.5708 0 0</pose>
      <parent>robot_base_link</parent>
      <child>rear_left_wheel_link</child>
      <axis>
          <xyz>0 0 -1</xyz>
          <use_parent_model_frame>true</use_parent_model_frame>
          <limit>
            <lower>-1e+16</lower>
            <upper>1e+16</upper>
          </limit>
          <dynamics>
            <spring_reference>0</spring_reference>
            <spring_stiffness>0</spring_stiffness>
          </dynamics>
      </axis>
      <physics>
        <ode>
          <limit>
            <cfm>0.000000</cfm>
            <erp>0.900000</erp>
          </limit>
        </ode>
      </physics>
    </joint>

    <link name='rear_left_wheel_link'>
      <pose relative_to='rear_left_wheel_joint'>0 0 0 0 0 0</pose>
      <inertial>
        <pose>0 0 0 0 0 0</pose>
        <mass>0.176</mass>
        <inertia>
          <ixx>0.000287467</ixx>
          <ixy>0</ixy>
          <ixz>0</ixz>
          <iyy>0.000287467</iyy>
          <iyz>0</iyz>
          <izz>3.0184e-05</izz>
        </inertia>
      </inertial>
      <collision name='rear_left_wheel_link_collision'>
        <pose>0 0 0 0 0 0</pose>
        <geometry>
          <cylinder>
            <length>0.0615</length>
            <radius>0.068</radius>
          </cylinder>
        </geometry>
        <surface>
          <friction>
            <ode>
              <mu>2</mu>
              <mu2>2</mu2>
              <slip1>0.0</slip1>
              <slip2>0.0</slip2>
            </ode>
          </friction>
        </surface>
      </collision>
      <visual name='rear_left_wheel_link_visual'>
        <pose>0 0 0 0 0 0</pose>
        <geometry>
          <cylinder>
            <length>0.0615</length>
            <radius>0.068</radius>
          </cylinder>
        </geometry>
        <material>
          <script>
            <name>Gazebo/Black</name>
            <uri>file://media/materials/scripts/gazebo.material</uri> 
          </script>
        </material>
      </visual>
    </link>

    <joint name='rear_right_wheel_joint' type='revolute'>
      <pose relative_to='robot_base_link'>-0.0955 -0.141 0 1.5708 0 0</pose>
      <parent>robot_base_link</parent>
      <child>rear_right_wheel_link</child>
      <axis>
          <xyz>0 0 -1</xyz>
          <use_parent_model_frame>true</use_parent_model_frame>
          <limit>
            <lower>-1e+16</lower>
            <upper>1e+16</upper>
          </limit>
          <dynamics>
            <spring_reference>0</spring_reference>
            <spring_stiffness>0</spring_stiffness>
          </dynamics>
      </axis>
      <physics>
        <ode>
          <limit>
            <cfm>0.000000</cfm>
            <erp>0.900000</erp>
          </limit>
        </ode>
      </physics>
    </joint>

    <link name='rear_right_wheel_link'>
      <pose relative_to='rear_right_wheel_joint'>0 0 0 0 0 0</pose>
      <inertial>
        <pose>0 0 0 0 0 0</pose>
        <mass>0.176</mass>
        <inertia>
          <ixx>0.000287467</ixx>
          <ixy>0</ixy>
          <ixz>0</ixz>
          <iyy>0.000287467</iyy>
          <iyz>0</iyz>
          <izz>3.0184e-05</izz>
        </inertia>
      </inertial>
      <collision name='rear_right_wheel_link_collision'>
        <pose>0 0 0 0 0 0</pose>
        <geometry>
          <cylinder>
            <length>0.0615</length>
            <radius>0.068</radius>
          </cylinder>
        </geometry>
        <surface>
          <friction>
            <ode>
              <mu>2</mu>
              <mu2>2</mu2>
              <slip1>0.0</slip1>
              <slip2>0.0</slip2>
            </ode>
          </friction>
        </surface>
      </collision>
      <visual name='rear_right_wheel_link_visual'>
        <pose>0 0 0 0 0 0</pose>
        <geometry>
          <cylinder>
            <length>0.0615</length>
            <radius>0.068</radius>
          </cylinder>
        </geometry>
        <material>
          <script>
            <name>Gazebo/Black</name>
            <uri>file://media/materials/scripts/gazebo.material</uri> 
          </script>
        </material>
      </visual>
    </link>
    <!-- Drive plugin  -->
    <plugin name="mars_robot_drive_plugin" filename="libgazebo_ros_diff_drive.so">
      <update_rate>100.0</update_rate>
      <num_wheel_pairs>2</num_wheel_pairs>
      <left_joint>front_left_wheel_joint</left_joint>
      <right_joint>front_right_wheel_joint</right_joint>
      <left_joint>rear_left_wheel_joint</left_joint>
      <right_joint>rear_right_wheel_joint</right_joint>
      <wheel_separation>0.191</wheel_separation>
      <wheel_separation>0.191</wheel_separation>
      <wheel_diameter>0.246</wheel_diameter>
      <wheel_diameter>0.246</wheel_diameter>
      <max_wheel_torque>30</max_wheel_torque>
      <publish_odom>true</publish_odom>
      <publish_odom_tf>true</publish_odom_tf>
      <publish_wheel_tf>true</publish_wheel_tf>
      <odometry_frame>odom</odometry_frame>
      <robot_base_frame>mars_robot_footprint</robot_base_frame>
    </plugin> 

    <static>0</static>
    <!-- <plugin name='gazebo_ros_control' filename='libgazebo_ros_control.so'>
      <robotNamespace>/mars_robot</robotNamespace>
      <robotSimType>gazebo_ros_control/DefaultRobotHWSim</robotSimType>
    </plugin> -->
  </model>
</sdf>

