<?xml version="1.0" ?>
<!-- =================================================================================== -->
<!-- |    This document was autogenerated by xacro from mars_robot.urdf.xacro          | -->
<!-- |    EDITING THIS FILE BY HAND IS NOT RECOMMENDED                                 | -->
<!-- =================================================================================== -->
<robot name="mars_robot">
  <gazebo>
    <plugin filename="libgazebo_ros_control.so" name="gazebo_ros_control">
      <robotNamespace>/mars_robot</robotNamespace>
      <robotSimType>gazebo_ros_control/DefaultRobotHWSim</robotSimType>
    </plugin>
  </gazebo>
  <gazebo reference="robot_base_link">
    <material>Gazebo/Red</material>
  </gazebo>
  <gazebo reference="front_left_wheel_link">
    <mu1>0.2</mu1>
    <mu2>0.2</mu2>
    <material>Gazebo/Black</material>
  </gazebo>
  <gazebo reference="front_right_wheel_link">
    <mu1>0.2</mu1>
    <mu2>0.2</mu2>
    <material>Gazebo/Black</material>
  </gazebo>
  <gazebo reference="rear_left_wheel_link">
    <mu1>0.2</mu1>
    <mu2>0.2</mu2>
    <material>Gazebo/Black</material>
  </gazebo>
  <gazebo reference="rear_right_wheel_link">
    <mu1>0.2</mu1>
    <mu2>0.2</mu2>
    <material>Gazebo/Black</material>
  </gazebo>
  <gazebo reference="camera_link">
    <mu1>0.2</mu1>
    <mu2>0.2</mu2>
    <material>Gazebo/Orange</material>
  </gazebo>
  <gazebo reference="imu_link">
    <mu1>0.2</mu1>
    <mu2>0.2</mu2>
    <material>Gazebo/Black</material>
  </gazebo>
  <gazebo reference="camera_link">
    <sensor name="camera1" type="camera">
      <update_rate>30.0</update_rate>
      <camera name="head">
        <horizontal_fov>1.3962634</horizontal_fov>
        <image>
          <width>800</width>
          <height>800</height>
          <format>R8G8B8</format>
        </image>
        <clip>
          <near>0.02</near>
          <far>300</far>
        </clip>
        <noise>
          <type>gaussian</type>
          <!-- Noise is sampled independently per pixel on each frame.
               That pixel's noise value is added to each of its color
               channels, which at that point lie in the range [0,1]. -->
          <mean>0.0</mean>
          <stddev>0.007</stddev>
        </noise>
      </camera>
      <plugin filename="libgazebo_ros_camera.so" name="camera_controller">
        <alwaysOn>true</alwaysOn>
        <updateRate>0.0</updateRate>
        <cameraName>mars_robot/camera1</cameraName>
        <imageTopicName>image_raw</imageTopicName>
        <cameraInfoTopicName>camera_info</cameraInfoTopicName>
        <frameName>camera_link_optical</frameName>
        <!-- setting hackBaseline to anything but 0.0 will cause a misalignment
            between the gazebo sensor image and the frame it is supposed to
            be attached to -->
        <hackBaseline>0.0</hackBaseline>
        <distortionK1>0.0</distortionK1>
        <distortionK2>0.0</distortionK2>
        <distortionK3>0.0</distortionK3>
        <distortionT1>0.0</distortionT1>
        <distortionT2>0.0</distortionT2>
        <CxPrime>0</CxPrime>
        <Cx>0.0</Cx>
        <Cy>0.0</Cy>
        <focalLength>0.0</focalLength>
      </plugin>
    </sensor>
  </gazebo>
  <gazebo reference="imu_link">
    <gravity>true</gravity>
    <sensor name="imu_sensor" type="imu">
      <always_on>true</always_on>
      <update_rate>100</update_rate>
      <visualize>true</visualize>
      <topic>__default_topic__</topic>
      <plugin filename="libgazebo_ros_imu_sensor.so" name="imu_plugin">
        <topicName>imu</topicName>
        <bodyName>imu_link</bodyName>
        <updateRateHZ>10.0</updateRateHZ>
        <gaussianNoise>0.0</gaussianNoise>
        <xyzOffset>0 0 0</xyzOffset>
        <rpyOffset>0 0 0</rpyOffset>
        <frameName>imu_link</frameName>
        <initialOrientationAsReference>false</initialOrientationAsReference>
      </plugin>
      <pose>0 0 0 0 0 0</pose>
    </sensor>
  </gazebo>
  <!-- This first link, "world" is empty-->
  <link name="mars_robot_footprint"/>
  <link name="robot_base_link">
    <visual>
      <origin rpy="0.0 0.0 0.0" xyz="0 0 0.1115"/>
      <geometry>
        <!-- <mesh filename="file:///workspaces/2022-TUB-MARS-autopilot/src/mars_robot/meshes/Robot_base.stl"
                        scale="0.001 0.001 0.001"/>            -->
        <box size="0.326 0.2142 0.175"/>
      </geometry>
      <material name="red">
        <color rgba="1.0 0.0 0.0 1.0"/>
      </material>
    </visual>
    <inertial>
      <mass value="4.42"/>
      <origin rpy="0 0 0" xyz="0 0 0"/>
      <inertia ixx="0.03295736167" ixy="0.0" ixz="0.0" iyy="0.05523416167" iyz="0.0" izz="0.05601318667"/>
    </inertial>
    <collision>
      <origin rpy="0 0 0" xyz="0 0 0.1115"/>
      <geometry>
        <box size="0.326 0.2142 0.300"/>
      </geometry>
    </collision>
  </link>
  <!-- Fixed joint from "world" to "base"-->
  <joint name="base_joint" type="fixed">
    <preserveFixedJoint>true</preserveFixedJoint>
    <origin rpy="0 0 0" xyz="0.0 0 0.0615"/>
    <parent link="mars_robot_footprint"/>
    <child link="robot_base_link"/>
  </joint>
  <link name="front_left_wheel_link">
    <visual>
      <origin rpy="0 0 0" xyz="0 0 0"/>
      <geometry>
        <!-- <mesh filename="file:///workspaces/2022-TUB-MARS-autopilot/src/mars_robot/meshes/Wheel_one.stl" 
                        scale="0.001 0.001 0.001"/> -->
        <cylinder length="0.068" radius="0.0615"/>
      </geometry>
      <material name="color_wheel">
        <color rgba="0.0 0.0 0.0 1.0"/>
      </material>
    </visual>
    <collision>
      <origin rpy="0 0 0" xyz="0 0 0"/>
      <geometry>
        <cylinder length="0.068" radius="0.0615"/>
      </geometry>
    </collision>
    <inertial>
      <mass value="0.176"/>
      <inertia ixx="2.87466667e-04" ixy="0.0" ixz="0.0" iyy="2.87466667e-04" iyz="0.0" izz="3.0184e-05"/>
    </inertial>
  </link>
  <joint name="front_left_wheel_joint" type="continuous">
    <preserveFixedJoint>true</preserveFixedJoint>
    <parent link="robot_base_link"/>
    <child link="front_left_wheel_link"/>
    <origin rpy="1.5708 0 0" xyz="0.0955 0.141 0"/>
    <implicitSpringDamper>1</implicitSpringDamper>
  </joint>
  <link name="front_right_wheel_link">
    <visual>
      <origin rpy="0 0 0" xyz="0 0 0"/>
      <geometry>
        <!-- <mesh filename="file:///workspaces/2022-TUB-MARS-autopilot/src/mars_robot/meshes/Wheel_two.stl" 
                        scale="0.001 0.001 0.001"/> -->
        <cylinder length="0.068" radius="0.0615"/>
      </geometry>
      <material name="color_wheel">
        <color rgba="0.0 0.0 0.0 1.0"/>
      </material>
    </visual>
    <collision>
      <origin rpy="0 0 0" xyz="0 0 0"/>
      <geometry>
        <cylinder length="0.068" radius="0.0615"/>
      </geometry>
    </collision>
    <inertial>
      <mass value="0.176"/>
      <inertia ixx="2.87466667e-04" ixy="0.0" ixz="0.0" iyy="2.87466667e-04" iyz="0.0" izz="3.0184e-05"/>
    </inertial>
  </link>
  <joint name="front_right_wheel_joint" type="continuous">
    <preserveFixedJoint>true</preserveFixedJoint>
    <parent link="robot_base_link"/>
    <child link="front_right_wheel_link"/>
    <origin rpy="1.5708 0 0" xyz="0.0955 -0.141 0"/>
    <implicitSpringDamper>1</implicitSpringDamper>
  </joint>
  <link name="rear_left_wheel_link">
    <visual>
      <origin rpy="0 0 0" xyz="0 0 0"/>
      <geometry>
        <!-- <mesh filename="file:///workspaces/2022-TUB-MARS-autopilot/src/mars_robot/meshes/Wheel_three.stl" 
                        scale="0.001 0.001 0.001"/> -->
        <cylinder length="0.068" radius="0.0615"/>
      </geometry>
      <material name="color_wheel">
        <color rgba="0.0 0.0 0.0 1.0"/>
      </material>
    </visual>
    <collision>
      <origin rpy="0 0 0" xyz="0 0 0"/>
      <geometry>
        <cylinder length="0.068" radius="0.0615"/>
      </geometry>
    </collision>
    <inertial>
      <mass value="0.176"/>
      <inertia ixx="2.87466667e-04" ixy="0.0" ixz="0.0" iyy="2.87466667e-04" iyz="0.0" izz="3.0184e-05"/>
    </inertial>
  </link>
  <joint name="rear_left_wheel_joint" type="continuous">
    <preserveFixedJoint>true</preserveFixedJoint>
    <parent link="robot_base_link"/>
    <child link="rear_left_wheel_link"/>
    <origin rpy="1.5708 0 0" xyz="-0.0955 0.141 0"/>
    <implicitSpringDamper>1</implicitSpringDamper>
  </joint>
  <link name="rear_right_wheel_link">
    <visual>
      <origin rpy="0 0 0" xyz="0 0 0"/>
      <geometry>
        <!-- <mesh filename="file:///workspaces/2022-TUB-MARS-autopilot/src/mars_robot/meshes/Wheel_four.stl" 
                        scale="0.001 0.001 0.001"/> -->
        <cylinder length="0.068" radius="0.0615"/>
      </geometry>
      <material name="color_wheel">
        <color rgba="0.0 0.0 0.0 1.0"/>
      </material>
    </visual>
    <collision>
      <origin rpy="0 0 0" xyz="0 0 0"/>
      <geometry>
        <cylinder length="0.068" radius="0.0615"/>
      </geometry>
    </collision>
    <inertial>
      <mass value="0.176"/>
      <inertia ixx="2.87466667e-04" ixy="0.0" ixz="0.0" iyy="2.87466667e-04" iyz="0.0" izz="3.0184e-05"/>
    </inertial>
  </link>
  <joint name="rear_right_wheel_joint" type="continuous">
    <preserveFixedJoint>true</preserveFixedJoint>
    <parent link="robot_base_link"/>
    <child link="rear_right_wheel_link"/>
    <origin rpy="1.5708 0 0" xyz="-0.0955 -0.141 0"/>
    <implicitSpringDamper>1</implicitSpringDamper>
  </joint>
  <!--IMU-->
  <link name="imu_link">
    <inertial>
      <mass value="0.010"/>
      <origin rpy="0 0 0" xyz="0 0 0"/>
      <inertia ixx="1e-09" ixy="0.0" ixz="0.0" iyy="1e-09" iyz="0.0" izz="1e-09"/>
    </inertial>
  </link>
  <joint name="imu_joint" type="fixed">
    <preserveFixedJoint>true</preserveFixedJoint>
    <parent link="robot_base_link"/>
    <child link="imu_link"/>
    <origin rpy="0 0 0" xyz="0.0495 0.01 0.0665"/>
  </joint>
  <!--CAMERA-->
  <link name="camera_link">
    <visual>
      <geometry>
        <box size="0.03 0.11 0.035"/>
      </geometry>
      <material name="color_cam">
        <color rgba="1.0 0.65 0.0 1.0"/>
      </material>
    </visual>
  </link>
  <joint name="camera_joint" type="fixed">
    <preserveFixedJoint>true</preserveFixedJoint>
    <origin rpy="0 0 0" xyz="0.1335 0 0.2045"/>
    <parent link="robot_base_link"/>
    <child link="camera_link"/>
  </joint>
  <!-- generate an optical frame http://www.ros.org/reps/rep-0103.html#suffix-frames
      so that ros and opencv can operate on the camera frame correctly -->
  <joint name="camera_optical_joint" type="fixed">
    <preserveFixedJoint>true</preserveFixedJoint>
    <!-- these values have to be these values otherwise the gazebo camera image
        won't be aligned properly with the frame it is supposedly originating from -->
    <origin rpy="-1.5707963267948966 0 -1.5707963267948966" xyz="0 0 0"/>
    <parent link="camera_link"/>
    <child link="camera_link_optical"/>
  </joint>
  <link name="camera_link_optical"/>
</robot>
