<?xml version="1.0"?>
<robot name="jackal">
  <material name="dark_grey">
    <color rgba="0.2 0.2 0.2 1.0" />
  </material>
  <material name="light_grey">
    <color rgba="0.4 0.4 0.4 1.0" />
  </material>
  <material name="yellow">
    <color rgba="0.8 0.8 0.0 1.0" />
  </material>
  <material name="black">
    <color rgba="0.15 0.15 0.15 1.0" />
  </material>
  <!-- JACKAL BASE -->
  <!-- ..................... -->
  <link name="base_footprint" />
  <link name="base_link">
    <visual>
      <origin rpy="1.57079632679 0 1.57079632679" xyz="0 0 -0.0655" />
      <geometry>
        <mesh filename="file:///workspaces/2022-TUB-MARS-autopilot/src/jackal_custom/meshes/jackal-base.stl" />
      </geometry>
      <material name="dark_grey" />
    </visual>
    <collision>
      <origin xyz="0 0 0.092" />
      <geometry>
        <box size="0.42 0.31 0.184" />
      </geometry>
    </collision>
    <inertial>
      <!-- Center of mass -->
      <origin rpy="0 0 0" xyz="0.012  0.002 0.067" />
      <mass value="16.523" />
      <!-- Moments of inertia: ( chassis without wheels ) -->
      <inertia ixx="0.3136" ixy="-0.0008" ixz="0.0164" iyy="0.3922" iyz="-0.0009" izz="0.4485" />
    </inertial>
  </link>
  <joint name="base_footprint_joint" type="fixed">
    <origin rpy="0 0 0" xyz="0 0 0" />
    <parent link="base_footprint" />
    <child link="base_link" />
  </joint>
  <link name="front_left_wheel_link">
    <visual>
      <origin rpy="0 0 0" xyz="0 0 0" />
      <geometry>
        <mesh filename="file:///workspaces/2022-TUB-MARS-autopilot/src/jackal_custom/meshes/jackal-wheel.stl" />
      </geometry>
      <material name="black" />
    </visual>
    <collision>
      <origin rpy="0 0 0" xyz="0 0 0" />
      <geometry>
        <cylinder length="0.04" radius="0.098" />
      </geometry>
    </collision>
    <inertial>
      <origin rpy="0 0 0" xyz="0 0 0" />
      <mass value="0.477" />
      <inertia ixx="0.0013" ixy="0" ixz="0" iyy="0.0024" iyz="0" izz="0.0013" />
    </inertial>
  </link>
  <joint name="front_left_wheel_joint" type="continuous">
    <parent link="base_link" />
    <child link="front_left_wheel_link" />
    <origin rpy="0 0 0" xyz="0.131 0.187795 0.0345" />
    <axis xyz="0 1 0" />
  </joint>
  <link name="front_right_wheel_link">
    <visual>
      <origin rpy="0 0 0" xyz="0 0 0" />
      <geometry>
        <mesh filename="file:///workspaces/2022-TUB-MARS-autopilot/src/jackal_custom/meshes/jackal-wheel.stl" />
      </geometry>
      <material name="black" />
    </visual>
    <collision>
      <origin rpy="0 0 0" xyz="0 0 0" />
      <geometry>
        <cylinder length="0.04" radius="0.098" />
      </geometry>
    </collision>
    <inertial>
      <origin rpy="0 0 0" xyz="0 0 0" />
      <mass value="0.477" />
      <inertia ixx="0.0013" ixy="0" ixz="0" iyy="0.0024" iyz="0" izz="0.0013" />
    </inertial>
  </link>
  <joint name="front_right_wheel_joint" type="continuous">
    <parent link="base_link" />
    <child link="front_right_wheel_link" />
    <origin rpy="0 0 0" xyz="0.131 -0.187795 0.0345" />
    <axis xyz="0 1 0" />
  </joint>
  <link name="rear_left_wheel_link">
    <visual>
      <origin rpy="0 0 0" xyz="0 0 0" />
      <geometry>
        <mesh filename="file:///workspaces/2022-TUB-MARS-autopilot/src/jackal_custom/meshes/jackal-wheel.stl" />
      </geometry>
      <material name="black" />
    </visual>
    <collision>
      <origin rpy="0 0 0" xyz="0 0 0" />
      <geometry>
        <cylinder length="0.04" radius="0.098" />
      </geometry>
    </collision>
    <inertial>
      <origin rpy="0 0 0" xyz="0 0 0" />
      <mass value="0.477" />
      <inertia ixx="0.0013" ixy="0" ixz="0" iyy="0.0024" iyz="0" izz="0.0013" />
    </inertial>
  </link>
  <joint name="rear_left_wheel_joint" type="continuous">
    <parent link="base_link" />
    <child link="rear_left_wheel_link" />
    <origin rpy="0 0 0" xyz="-0.131 0.187795 0.0345" />
    <axis xyz="0 1 0" />
  </joint>
  <link name="rear_right_wheel_link">
    <visual>
      <origin rpy="0 0 0" xyz="0 0 0" />
      <geometry>
        <mesh filename="file:///workspaces/2022-TUB-MARS-autopilot/src/jackal_custom/meshes/jackal-wheel.stl" />
      </geometry>
      <material name="black" />
    </visual>
    <collision>
      <origin rpy="0 0 0" xyz="0 0 0" />
      <geometry>
        <cylinder length="0.04" radius="0.098" />
      </geometry>
    </collision>
    <inertial>
      <origin rpy="0 0 0" xyz="0 0 0" />
      <mass value="0.477" />
      <inertia ixx="0.0013" ixy="0" ixz="0" iyy="0.0024" iyz="0" izz="0.0013" />
    </inertial>
  </link>
  <joint name="rear_right_wheel_joint" type="continuous">
    <parent link="base_link" />
    <child link="rear_right_wheel_link" />
    <origin rpy="0 0 0" xyz="-0.131 -0.187795 0.0345" />
    <axis xyz="0 1 0" />
  </joint>
  <link name="front_fender_link">
    <visual>
      <geometry>
        <mesh filename="file:///workspaces/2022-TUB-MARS-autopilot/src/jackal_custom/meshes/jackal-fender.stl" />
      </geometry>
      <material name="yellow" />
    </visual>
    <collision>
      <geometry>
        <mesh filename="file:///workspaces/2022-TUB-MARS-autopilot/src/jackal_custom/meshes/jackal-fender.stl" />
      </geometry>
    </collision>
  </link>
  <joint name="front_fender_joint" type="fixed">
    <origin rpy="0 0 0" xyz="0 0 0" />
    <parent link="base_link" />
    <child link="front_fender_link" />
  </joint>
  <link name="rear_fender_link">
    <visual>
      <geometry>
        <mesh filename="file:///workspaces/2022-TUB-MARS-autopilot/src/jackal_custom/meshes/jackal-fender.stl" />
      </geometry>
      <material name="yellow" />
    </visual>
    <collision>
      <geometry>
        <mesh filename="file:///workspaces/2022-TUB-MARS-autopilot/src/jackal_custom/meshes/jackal-fender.stl" />
      </geometry>
    </collision>
  </link>
  <joint name="rear_fender_joint" type="fixed">
    <origin rpy="0 0 3.14159265359" xyz="0 0 0" />
    <parent link="base_link" />
    <child link="rear_fender_link" />
  </joint>
  <link name="imu_link">
    <inertial>
      <mass value="0.010" />
      <origin rpy="0 0 0" xyz="0 0 0" />
      <inertia ixx="1e-09" ixy="0.0" ixz="0.0" iyy="1e-09" iyz="0.0" izz="1e-09" />
    </inertial>
  </link>
  <joint name="imu_joint" type="fixed">
    <parent link="base_link" />
    <child link="imu_link" />
  </joint>
  <link name="navsat_link">
    <visual>
      <geometry>
        <cylinder length="0.016" radius="0.026" />
      </geometry>
      <origin xyz="0 0 0.008" />
      <material name="black" />
    </visual>
  </link>
  <joint name="navsat_joint" type="fixed">
    <parent link="base_link" />
    <child link="navsat_link" />
    <origin xyz="-0.180 0.126 0.1815" />
  </joint>
  <link name="mid_mount" />
  <joint name="mid_mount_joint" type="fixed">
    <parent link="base_link" />
    <child link="mid_mount" />
    <origin xyz="0 0 0.184" />
  </joint>
  <link name="rear_mount" />
  <joint name="rear_mount_joint" type="fixed">
    <parent link="mid_mount" />
    <child link="rear_mount" />
    <origin xyz="-0.12 0 0" />
  </joint>
  <link name="front_mount" />
  <joint name="front_mount_joint" type="fixed">
    <parent link="mid_mount" />
    <child link="front_mount" />
    <origin xyz="0.12 0 0" />
  </joint>
  <link name="left_antenna_link">
    <visual>
      <origin rpy="0 0 0" xyz="0 0 0" />
      <geometry>
        <cylinder length="0.16" radius="0.012" />
      </geometry>
      <material name="dark_grey" />
    </visual>
    <collision>
      <origin rpy="0 0 0" xyz="0 0 0" />
      <geometry>
        <cylinder length="0.16" radius="0.01" />
      </geometry>
    </collision>
    <inertial>
      <origin rpy="0 0 0" xyz="0.0 0.0 0.065" />
      <mass value="0.025" />
      <inertia ixx="0.000021209" ixy="-2.7e-08" ixz="-3.24078261e-08" iyy="3.9202e-05" iyz="-6.258e-06" izz="0.000186722" />
    </inertial>
  </link>
  <joint name="left_antenna_joint" type="fixed">
    <origin rpy="0 0 0" xyz="0.0 -0.12 0.06" />
    <parent link="rear_mount" />
    <child link="left_antenna_link" />
  </joint>
  <link name="right_antenna_link">
    <visual>
      <origin rpy="0 0 0" xyz="0 0 0" />
      <geometry>
        <cylinder length="0.16" radius="0.012" />
      </geometry>
      <material name="dark_grey" />
    </visual>
    <collision>
      <origin rpy="0 0 0" xyz="0 0 0" />
      <geometry>
        <cylinder length="0.16" radius="0.01" />
      </geometry>
    </collision>
    <inertial>
      <origin rpy="0 0 0" xyz="0.0 0.0 0.065" />
      <mass value="0.025" />
      <inertia ixx="0.000021209" ixy="-2.7e-08" ixz="-3.24078261e-08" iyy="3.9202e-05" iyz="-6.258e-06" izz="0.000186722" />
    </inertial>
  </link>
  <joint name="right_antenna_joint" type="fixed">
    <origin rpy="0 0 0" xyz="0.0 0.12 0.06" />
    <parent link="rear_mount" />
    <child link="right_antenna_link" />
  </joint>
  <!-- LASER SCANNER -->
  <!-- ..................... -->
  <link name="laser_link">
    <inertial>
      <mass value="1.1" />
      <origin xyz="0 0 0" />
      <inertia ixx="0.00307156543804" ixy="0.0" ixz="0.0" iyy="0.00312849041527" iyz="0.0" izz="0.00196432421427" />
    </inertial>
    <visual>
      <origin rpy="0 0 0" xyz="0 0 0" />
      <geometry>
        <!-- Origin of this mesh is the focal point of the LIDAR. -->
        <mesh filename="file:///workspaces/2022-TUB-MARS-autopilot/src/jackal_custom/meshes/sick-lms1xx.stl" />
      </geometry>
      <material name="light_grey">
        <color rgba="0.8 0.8 0.8 0.8" />
      </material>
    </visual>
    <collision>
      <origin rpy="0 0 0" xyz="0 0 -0.05" />
      <geometry>
        <box size="0.105 0.1 0.1" />
      </geometry>
    </collision>
  </link>
  <link name="laser_mount">
    <visual>
      <origin rpy="0 0 0" xyz="0 0 0" />
      <geometry>
        <!-- Origin of this mesh is the base of the bracket. -->
        <mesh filename="file:///workspaces/2022-TUB-MARS-autopilot/src/jackal_custom/meshes/sick-lms1xx-bracket.stl" />
      </geometry>
      <material name="dark_grey" />
    </visual>
  </link>
  <joint name="laser_joint" type="fixed">
    <!-- This offset is from the base of the bracket to the LIDAR's focal point. -->
    <origin rpy="3.14159265359 0 0" xyz="0 0 0.06" />
    <parent link="laser_mount" />
    <child link="laser_link" />
  </joint>
  <joint name="laser_mount_joint" type="fixed">
    <parent link="front_mount" />
    <child link="laser_mount" />
    <origin xyz="0 0 0.05" />
  </joint>
  <!-- Camera -->
  <link name="camera_link">
    <visual>
      <geometry>
        <box size="0.02 0.02 0.02" />
      </geometry>
      <material name="black" />
    </visual>
  </link>
  <joint name="camera_joint" type="fixed">
    <origin rpy="0 0 0" xyz="0 0 -0.125" />
    <parent link="laser_link" />
    <child link="camera_link" />
  </joint>
  <link name="camera_lens_link">
    <visual>
      <geometry>
        <cylinder length="0.03" radius="0.007" />
      </geometry>
      <material name="black" />
    </visual>
  </link>
  <joint name="camera_lens_joint" type="fixed">
    <origin rpy="0 1.57079632679 0" xyz="0.025 0 0" />
    <parent link="camera_link" />
    <child link="camera_lens_link" />
  </joint>
</robot>