<?xml version="1.0"?>
<sdf version="1.7">
  <model name="jackal">
    <pose>0 0 0.5 0 0 0</pose>
    <link name="base_footprint" />
    <!-- Main Chassis -->
    <link name="base_link">
      <visual name="chassis_visual">
        <pose>0 0 -0.0655 1.57079632679 0 1.57079632679</pose>
        <geometry>
          <mesh>
            <uri>file:///workspaces/2022-TUB-MARS-autopilot/src/jackal_custom/meshes/jackal-base.stl</uri>
          </mesh>
        </geometry>
        <material>
          <script>
            <name>Gazebo/DarkGrey</name>
          </script>
        </material>
      </visual>
      <collision name="chassis_collision">
        <pose>0 0 0.092 0 0 0</pose>
        <geometry>
          <box>
            <size>0.42 0.31 0.184</size>
          </box>
        </geometry>
      </collision>
      <inertial>
        <pose>0.002 0.067 0 0 0 0.012</pose>
        <mass>16.523</mass>
        <inertia>
          <ixx>0.3136</ixx>
          <ixy>-0.0008</ixy>
          <ixz>0.0164</ixz>
          <iyy>0.3922</iyy>
          <iyz>-0.0009</iyz>
          <izz>0.4485</izz>
        </inertia>
      </inertial>
    </link>
    <joint name="base_footprint_joint" type="fixed">
      <parent>base_footprint</parent>
      <child>base_link</child>
    </joint>
    <!-- front left wheel -->
    <link name="front_left_wheel_link">
      <pose>0.131 0.187795 0.0345 1.57079632679 0 0</pose>
      <visual name="front_left_wheel_visual">
        <geometry>
          <mesh>
            <uri>file:///workspaces/2022-TUB-MARS-autopilot/src/jackal_custom/meshes/jackal-wheel.stl</uri>
          </mesh>
        </geometry>
        <material>
          <script>
            <name>Gazebo/Black</name>
          </script>
        </material>
      </visual>
      <collision name="front_left_wheel_collision">
        <geometry>
          <cylinder>
            <length>0.04</length>
            <radius>0.098</radius>
          </cylinder>
        </geometry>
        <surface>
          <friction>
            <ode>
              <mu>2</mu>
              <mu2>2</mu2>
              <slip1>0.0</slip1>
              <slip2>0.0</slip2>
            </ode>
          </friction>
        </surface>
      </collision>
      <inertial>
        <mass>0.477</mass>
        <inertia>
          <ixx>0.0013</ixx>
          <ixy>0</ixy>
          <ixz>0</ixz>
          <iyy>0.0024</iyy>
          <iyz>0</iyz>
          <izz>0.0013</izz>
        </inertia>
      </inertial>
    </link>
    <joint name="front_left_wheel_joint" type="revolute">
      <parent>base_link</parent>
      <child>front_left_wheel_link</child>
      <axis>
        <xyz>0 0 -1</xyz>
        <use_parent_model_frame>true</use_parent_model_frame>
      </axis>
      <physics>
        <ode>
          <limit>
            <cfm>0.000000</cfm>
            <erp>0.900000</erp>
          </limit>
        </ode>
      </physics>
    </joint>
    <!-- front right wheel -->
    <link name="front_right_wheel_link">
      <pose>0.131 -0.187795 0.0345 1.57079632679 0 0</pose>
      <visual name="front_right_wheel_visual">
        <geometry>
          <mesh>
            <uri>file:///workspaces/2022-TUB-MARS-autopilot/src/jackal_custom/meshes/jackal-wheel.stl</uri>
          </mesh>
        </geometry>
        <material>
          <script>
            <name>Gazebo/Black</name>
          </script>
        </material>
      </visual>
      <collision name="front_right_wheel_collision">
        <geometry>
          <cylinder>
            <length>0.04</length>
            <radius>0.098</radius>
          </cylinder>
        </geometry>
        <surface>
          <friction>
            <ode>
              <mu>2</mu>
              <mu2>2</mu2>
              <slip1>0.0</slip1>
              <slip2>0.0</slip2>
            </ode>
          </friction>
        </surface>
      </collision>
      <inertial>
        <mass>0.477</mass>
        <inertia>
          <ixx>0.0013</ixx>
          <ixy>0</ixy>
          <ixz>0</ixz>
          <iyy>0.0024</iyy>
          <iyz>0</iyz>
          <izz>0.0013</izz>
        </inertia>
      </inertial>
    </link>
    <joint name="front_right_wheel_joint" type="revolute">
      <parent>base_link</parent>
      <child>front_right_wheel_link</child>
      <axis>
        <xyz>0 0 -1</xyz>
        <use_parent_model_frame>true</use_parent_model_frame>
      </axis>
      <physics>
        <ode>
          <limit>
            <cfm>0.000000</cfm>
            <erp>0.900000</erp>
          </limit>
        </ode>
      </physics>
    </joint>
    <!-- rear right wheel -->
    <link name="rear_right_wheel_link">
      <pose>-0.131 -0.187795 0.0345 1.57079632679 0 0</pose>
      <visual name="rear_right_wheel_visual">
        <geometry>
          <mesh>
            <uri>file:///workspaces/2022-TUB-MARS-autopilot/src/jackal_custom/meshes/jackal-wheel.stl</uri>
          </mesh>
        </geometry>
        <material>
          <script>
            <name>Gazebo/Black</name>
          </script>
        </material>
      </visual>
      <collision name="rear_right_wheel_collision">
        <geometry>
          <cylinder>
            <length>0.04</length>
            <radius>0.098</radius>
          </cylinder>
        </geometry>
        <surface>
          <friction>
            <ode>
              <mu>2</mu>
              <mu2>2</mu2>
              <slip1>0.0</slip1>
              <slip2>0.0</slip2>
            </ode>
          </friction>
        </surface>
      </collision>
      <inertial>
        <mass>0.477</mass>
        <inertia>
          <ixx>0.0013</ixx>
          <ixy>0</ixy>
          <ixz>0</ixz>
          <iyy>0.0024</iyy>
          <iyz>0</iyz>
          <izz>0.0013</izz>
        </inertia>
      </inertial>
    </link>
    <joint name="rear_right_wheel_joint" type="revolute">
      <parent>base_link</parent>
      <child>rear_right_wheel_link</child>
      <axis>
        <xyz>0 0 -1</xyz>
        <use_parent_model_frame>true</use_parent_model_frame>
      </axis>
      <physics>
        <ode>
          <limit>
            <cfm>0.000000</cfm>
            <erp>0.900000</erp>
          </limit>
        </ode>
      </physics>
    </joint>
    <!-- rear left wheel -->
    <link name="rear_left_wheel_link">
      <pose>-0.131 0.187795 0.0345 1.57079632679 0 0</pose>
      <visual name="rear_left_wheel_visual">
        <geometry>
          <mesh>
            <uri>file:///workspaces/2022-TUB-MARS-autopilot/src/jackal_custom/meshes/jackal-wheel.stl</uri>
          </mesh>
        </geometry>
        <material>
          <script>
            <name>Gazebo/Black</name>
          </script>
        </material>
      </visual>
      <collision name="rear_left_wheel_collision">
        <geometry>
          <cylinder>
            <length>0.04</length>
            <radius>0.098</radius>
          </cylinder>
        </geometry>
        <surface>
          <friction>
            <ode>
              <mu>2</mu>
              <mu2>2</mu2>
              <slip1>0.0</slip1>
              <slip2>0.0</slip2>
            </ode>
          </friction>
        </surface>
      </collision>
      <inertial>
        <mass>0.477</mass>
        <inertia>
          <ixx>0.0013</ixx>
          <ixy>0</ixy>
          <ixz>0</ixz>
          <iyy>0.0024</iyy>
          <iyz>0</iyz>
          <izz>0.0013</izz>
        </inertia>
      </inertial>
    </link>
    <joint name="rear_left_wheel_joint" type="revolute">
      <parent>base_link</parent>
      <child>rear_left_wheel_link</child>
      <axis>
        <xyz>0 0 -1</xyz>
        <use_parent_model_frame>true</use_parent_model_frame>
      </axis>
      <physics>
        <ode>
          <limit>
            <cfm>0.000000</cfm>
            <erp>0.900000</erp>
          </limit>
        </ode>
      </physics>
    </joint>
    <!-- Drive plugin -->
    <plugin name="jackal_drive_plugin" filename="libgazebo_ros_diff_drive.so">
      <update_rate>100.0</update_rate>
      <num_wheel_pairs>2</num_wheel_pairs>
      <left_joint>front_left_wheel_joint</left_joint>
      <right_joint>front_right_wheel_joint</right_joint>
      <left_joint>rear_left_wheel_joint</left_joint>
      <right_joint>rear_right_wheel_joint</right_joint>
      <wheel_separation>0.37559</wheel_separation>
      <wheel_separation>0.37559</wheel_separation>
      <wheel_diameter>0.196</wheel_diameter>
      <wheel_diameter>0.196</wheel_diameter>
      <max_wheel_torque>30</max_wheel_torque>
      <publish_odom>true</publish_odom>
      <publish_odom_tf>true</publish_odom_tf>
      <publish_wheel_tf>true</publish_wheel_tf>
      <odometry_frame>odom</odometry_frame>
      <robot_base_frame>base_footprint</robot_base_frame>
    </plugin>
    <!-- fenders -->
    <link name="front_fender_link">
      <pose>0 0 0 0 0 0</pose>
      <visual name="front_fender_visual">
        <geometry>
          <mesh>
            <uri>file:///workspaces/2022-TUB-MARS-autopilot/src/jackal_custom/meshes/jackal-fender.stl</uri>
          </mesh>
        </geometry>
        <material>
          <script>
            <name>Gazebo/Yellow</name>
          </script>
        </material>
      </visual>
      <collision name="front_fender_collision">
        <geometry>
          <mesh>
            <uri>file:///workspaces/2022-TUB-MARS-autopilot/src/jackal_custom/meshes/jackal-fender.stl</uri>
          </mesh>
        </geometry>
      </collision>
    </link>
    <joint name="front_fender_joint" type="fixed">
      <parent>base_link</parent>
      <child>front_fender_link</child>
    </joint>
    <link name="rear_fender_link">
      <pose>0 0 0 0 0 3.14159265359</pose>
      <visual name="rear_fender_visual">
        <geometry>
          <mesh>
            <uri>file:///workspaces/2022-TUB-MARS-autopilot/src/jackal_custom/meshes/jackal-fender.stl</uri>
          </mesh>
        </geometry>
        <material>
          <script>
            <name>Gazebo/Yellow</name>
          </script>
        </material>
      </visual>
      <collision name="rear_fender_collision">
        <geometry>
          <mesh>
            <uri>file:///workspaces/2022-TUB-MARS-autopilot/src/jackal_custom/meshes/jackal-fender.stl</uri>
          </mesh>
        </geometry>
      </collision>
    </link>
    <joint name="rear_fender_joint" type="fixed">
      <parent>base_link</parent>
      <child>rear_fender_link</child>
    </joint>
    <!-- Mounting points -->
    <link name="mid_mount">
      <pose relative_to="mid_mount_joint" />
    </link>
    <joint name="mid_mount_joint" type="fixed">
      <pose relative_to="base_link">0 0 0.184 0 0 0</pose>
      <parent>base_link</parent>
      <child>mid_mount</child>
    </joint>
    <link name="rear_mount">
      <pose relative_to="rear_mount_joint" />
    </link>
    <joint name="rear_mount_joint" type="fixed">
      <pose relative_to="mid_mount">-0.12 0 0 0 0 0</pose>
      <parent>mid_mount</parent>
      <child>rear_mount</child>
    </joint>
    <link name="front_mount">
      <pose relative_to="front_mount_joint" />
    </link>
    <joint name="front_mount_joint" type="fixed">
      <pose relative_to="mid_mount">0.12 0 0 0 0 0</pose>
      <parent>mid_mount</parent>
      <child>front_mount</child>
    </joint>
    <!-- Antennae -->
    <link name="left_antenna_link">
      <pose relative_to="left_antenna_joint" />
      <visual name="left_antenna_visual">
        <geometry>
          <cylinder>
            <length>0.16</length>
            <radius>0.012</radius>
          </cylinder>
        </geometry>
        <material>
          <script>
            <name>Gazebo/DarkGrey</name>
          </script>
        </material>
      </visual>
      <collision name="left_antenna_collision">
        <geometry>
          <cylinder>
            <length>0.16</length>
            <radius>0.012</radius>
          </cylinder>
        </geometry>
      </collision>
      <inertial>
        <mass>0.025</mass>
        <inertia>
          <ixx>0.000021209</ixx>
          <ixy>-2.7e-08</ixy>
          <ixz>-3.24078261e-08</ixz>
          <iyy>3.9202e-05</iyy>
          <iyz>-6.258e-06</iyz>
          <izz>0.000186722</izz>
        </inertia>
      </inertial>
    </link>
    <joint name="left_antenna_joint" type="fixed">
      <pose relative_to="rear_mount">0 -0.12 0.06 0 0 0</pose>
      <parent>rear_mount</parent>
      <child>left_antenna_link</child>
    </joint>
    <link name="right_antenna_link">
      <pose relative_to="right_antenna_joint" />
      <visual name="right_antenna_visual">
        <geometry>
          <cylinder>
            <length>0.16</length>
            <radius>0.012</radius>
          </cylinder>
        </geometry>
        <material>
          <script>
            <name>Gazebo/DarkGrey</name>
          </script>
        </material>
      </visual>
      <collision name="right_antenna_collision">
        <geometry>
          <cylinder>
            <length>0.16</length>
            <radius>0.012</radius>
          </cylinder>
        </geometry>
      </collision>
      <inertial>
        <mass>0.025</mass>
        <inertia>
          <ixx>0.000021209</ixx>
          <ixy>-2.7e-08</ixy>
          <ixz>-3.24078261e-08</ixz>
          <iyy>3.9202e-05</iyy>
          <iyz>-6.258e-06</iyz>
          <izz>0.000186722</izz>
        </inertia>
      </inertial>
    </link>
    <joint name="right_antenna_joint" type="fixed">
      <pose relative_to="rear_mount">0 0.12 0.06 0 0 0</pose>
      <parent>rear_mount</parent>
      <child>right_antenna_link</child>
    </joint>
    <!-- imu -->
    <link name="imu_link">
      <inertial>
        <mass>0.001</mass>
        <pose>0 0 0 0 0 0</pose>
        <inertia>
          <ixx>1e-09</ixx>
          <ixy>0.0</ixy>
          <ixz>0.0</ixz>
          <iyy>1e-09</iyy>
          <iyz>0.0</iyz>
          <izz>1e-09</izz>
        </inertia>
      </inertial>
      <sensor name="imu" type="imu">
        <always_on>true</always_on>
        <update_rate>250</update_rate>
        <imu>
          <angular_velocity>
            <x>
              <noise type="gaussian">
                <mean>0.0</mean>
                <stddev>2e-5</stddev>
              </noise>
            </x>
            <y>
              <noise type="gaussian">
                <mean>0.0</mean>
                <stddev>2e-5</stddev>
              </noise>
            </y>
            <z>
              <noise type="gaussian">
                <mean>0.0</mean>
                <stddev>2e-5</stddev>
              </noise>
            </z>
          </angular_velocity>
          <linear_acceleration>
            <x>
              <noise type="gaussian">
                <mean>0.0</mean>
                <stddev>1.7e-3</stddev>
              </noise>
            </x>
            <y>
              <noise type="gaussian">
                <mean>0.0</mean>
                <stddev>1.7e-3</stddev>
              </noise>
            </y>
            <z>
              <noise type="gaussian">
                <mean>0.0</mean>
                <stddev>1.7e-3</stddev>
              </noise>
            </z>
          </linear_acceleration>
        </imu>
        <plugin name="jackal_imu" filename="libgazebo_ros_imu_sensor.so">
          <ros>
            <remapping>~/out:=imu</remapping>
          </ros>
        </plugin>
      </sensor>
    </link>
    <joint name="imu_joint" type="fixed">
      <parent>base_link</parent>
      <child>imu_link</child>
    </joint>
    <!-- navsat gps -->
    <link name="navsat_link">
      <pose>-0.180 0.126 0.1815 0 0 0</pose>
      <visual name="navsat_visual">
        <geometry>
          <cylinder>
            <length>0.016</length>
            <radius>0.026</radius>
          </cylinder>
        </geometry>
        <material>
          <script>
            <name>Gazebo/Black</name>
          </script>
        </material>
      </visual>
    </link>
    <joint name="navsat_joint" type="fixed">
      <parent>base_link</parent>
      <child>navsat_link</child>
    </joint>
    <!-- LIDAR -->
    <link name="laser_link">
      <pose relative_to="laser_joint" />
      <inertial>
        <mass>1.1</mass>
        <inertia>
          <ixx>0.00307156543804</ixx>
          <ixy>0.0</ixy>
          <ixz>0.0</ixz>
          <iyy>0.00312849041527</iyy>
          <iyz>0.0</iyz>
          <izz>0.00196432421427</izz>
        </inertia>
      </inertial>
      <visual name="laser_visual">
        <geometry>
          <mesh>
            <uri>file:///workspaces/2022-TUB-MARS-autopilot/src/jackal_custom/meshes/sick-lms1xx.stl</uri>
          </mesh>
        </geometry>
        <material>
          <script>
            <name>Gazebo/Grey</name>
          </script>
        </material>
      </visual>
      <collision name="laser_collision">
        <geometry>
          <box>
            <size>0.105 0.1 0.1</size>
          </box>
        </geometry>
      </collision>
      <sensor type="gpu_ray" name="laser_sensor">
        <ray>
          <scan>
            <horizontal>
              <samples>720</samples>
              <resolution>1</resolution>
              <min_angle>-2.35619</min_angle>
              <max_angle>2.35619</max_angle>
            </horizontal>
          </scan>
          <range>
            <min>0.10</min>
            <max>30.0</max>
            <resolution>0.01</resolution>
          </range>
          <noise>
            <type>gaussian</type>
            <mean>0.0</mean>
            <stddev>0.01</stddev>
          </noise>
        </ray>
        <update_rate>30</update_rate>
        <plugin name="jackal_laserscan" filename="libgazebo_ros_ray_sensor.so">
          <ros>
            <remapping>~/out:=scan</remapping>
          </ros>
          <output_type>sensor_msgs/LaserScan</output_type>
          <frame_name>laser_link</frame_name>
        </plugin>
      </sensor>
    </link>
    <link name="laser_mount_link">
      <pose relative_to="laser_mount_joint" />
      <visual name="laser_mount_visual">
        <geometry>
          <mesh>
            <uri>file:///workspaces/2022-TUB-MARS-autopilot/src/jackal_custom/meshes/sick-lms1xx-bracket.stl</uri>
          </mesh>
        </geometry>
        <material>
          <script>
            <name>Gazebo/DarkGrey</name>
          </script>
        </material>
      </visual>
    </link>
    <joint name="laser_joint" type="fixed">
      <pose relative_to="laser_mount_link">0 0 0.06 3.14159265359 0 0</pose>
      <parent>laser_mount_link</parent>
      <child>laser_link</child>
    </joint>
    <joint name="laser_mount_joint" type="fixed">
      <pose relative_to="front_mount">0 0 0 0 0 0</pose>
      <parent>front_mount</parent>
      <child>laser_mount_link</child>
    </joint>
    <!-- Camera -->
    <link name="camera_link">
      <pose relative_to="camera_joint" />
      <inertial>
        <mass>0.1</mass>
        <inertia>
          <ixx>0.000166667</ixx>
          <iyy>0.000166667</iyy>
          <izz>0.000166667</izz>
        </inertia>
      </inertial>
      <collision name="camera_collision">
        <geometry>
          <box>
            <size>0.02 0.02 0.02</size>
          </box>
        </geometry>
      </collision>
      <visual name="camera_visual">
        <geometry>
          <box>
            <size>0.02 0.02 0.02</size>
          </box>
        </geometry>
        <material>
          <script>
            <name>Gazebo/Black</name>
          </script>
        </material>
      </visual>
    </link>
    <joint name="camera_joint" type="fixed">
      <pose relative_to="laser_link">0 0 -0.125 0 0 0</pose>
      <parent>laser_link</parent>
      <child>camera_link</child>
      <!-- <axis>
        <xyz>0 0 1</xyz>
        <limit>
          <effort>30</effort>
          <lower>-1.617</lower>
          <upper>1.617</upper>
          <velocity>1.571</velocity>
        </limit>
        <dynamics>
          <friction>0.13</friction>
        </dynamics>
      </axis> -->
    </joint>
    <link name="camera_lens_link">
      <pose relative_to="camera_lens_joint" />
      <visual name="camera_lens_visual">
        <geometry>
          <cylinder>
            <length>0.03</length>
            <radius>0.007</radius>
          </cylinder>
        </geometry>
        <material>
          <script>
            <name>Gazebo/Black</name>
          </script>
        </material>
      </visual>
      <collision name="camera_lens_collision">
        <geometry>
          <cylinder>
            <length>0.03</length>
            <radius>0.007</radius>
          </cylinder>
        </geometry>
      </collision>
      <sensor name="camera" type="camera">
        <pose>0 0 0 0 1.57079632679 3.14159265359</pose>
        <camera>
          <horizontal_fov>1.047</horizontal_fov>
          <image>
            <width>1280</width>
            <height>720</height>
          </image>
          <clip>
            <near>0.1</near>
            <far>100</far>
          </clip>
        </camera>
        <always_on>1</always_on>
        <update_rate>30</update_rate>
        <visualize>false</visualize>
        <plugin name="camera_driver" filename="libgazebo_ros_camera.so" />
      </sensor>
    </link>
    <joint name="camera_lens_joint" type="fixed">
      <pose relative_to="camera_link">0.025 0 0 0 -1.57079632679 0</pose>
      <parent>camera_link</parent>
      <child>camera_lens_link</child>
    </joint>
  </model>
</sdf>